{
    "comments": [
        {
            "author": "thomas.hentschel@novellus.com",
            "body": "Created attachment 168920\nthe test to reproduce the problem (needs junit...)\n\nadded test case to reproduce problem",
            "date": "20041217T04:45:42",
            "id": 0
        },
        {
            "author": "thomas.hentschel@novellus.com",
            "body": "Created attachment 168921\npatch\n\na patch that solves the problem for me",
            "date": "20041217T04:47:19",
            "id": 1
        },
        {
            "author": "thomas.hentschel@novellus.com",
            "body": "Created attachment 168923\nthe test again (forgot to include the src)",
            "date": "20041217T05:01:18",
            "id": 2
        },
        {
            "author": "igor@mir2.org",
            "body": "The bug is already fixed in Rhino 1.6R1 as a part of work on bug 258844",
            "date": "20041217T10:23:11",
            "id": 3
        }
    ],
    "component": "Core",
    "description": "In a scenario where multiple rhino interpreters are on the Java stack, and an\nexception is thrown during the execution of Java code (thru LiveConnect), an\nArrayOutOfBoundException may occur. The attached (junit) test reproduces the\nscenario in two ways: The 1st test succeeds, but the line number information for\nthe outer interpreter is corrupted, the 2nd test throws the\nArrayIndexOutOfBoundsException:\n\n---\norg.mozilla.javascript.WrappedException: WrappedException of \"oops\" in inner\nline 4 [null]\norg.mozilla.javascript.WrappedException: WrappedException of \"oops\" in outer1\nline 827 [null]\norg.mozilla.javascript.WrappedException: WrappedException of \"oops\" in inner\nline 4 [null]\n\njava.lang.ArrayIndexOutOfBoundsException\n  at org.mozilla.javascript.Interpreter.getShort(Interpreter.java:1411)\n  at\norg.mozilla.javascript.Interpreter.getSourcePositionFromStack(Interpreter.java:1817)\n  at org.mozilla.javascript.Context.getSourcePositionFromStack(Context.java:2297)\n  at org.mozilla.javascript.EvaluatorException.<init>(EvaluatorException.java:59)\n  at org.mozilla.javascript.WrappedException.<init>(WrappedException.java:78)\n  at org.mozilla.javascript.Context.throwAsScriptRuntimeEx(Context.java:1604)\n  at org.mozilla.javascript.MemberBox.invoke(MemberBox.java:191)\n  at org.mozilla.javascript.NativeJavaMethod.call(NativeJavaMethod.java:202)\n  at org.mozilla.javascript.Interpreter.interpret(Interpreter.java:2646)\n  at org.mozilla.javascript.InterpretedFunction.call(InterpretedFunction.java:57)\n  at\nrhinotestcase.ArrayOutOfBoundsRhinoTest.testArrayOutOfBoundsError2(ArrayOutOfBoundsRhinoTest.java:81)\n---\n\nThe attached patch fixes this behavior for me:\n---\norg.mozilla.javascript.WrappedException: WrappedException of \"oops\" in inner\nline 4 [null]\norg.mozilla.javascript.WrappedException: WrappedException of \"oops\" in outer1\nline 3 [null]\norg.mozilla.javascript.WrappedException: WrappedException of \"oops\" in inner\nline 4 [null]\norg.mozilla.javascript.WrappedException: WrappedException of \"oops\" in outer2\nline 2 [null]\n---\n\nThe test was run against 1.5R5, with the .optimizer package removed.",
    "hasPatch": true,
    "hasScreenshot": false,
    "id": "274996",
    "issuetypeClassified": "BUG",
    "issuetypeTracker": "BUG",
    "priority": "-- normal",
    "product": "Rhino",
    "project": "RHINO",
    "summary": "Exceptions with multiple interpreters on stack may lead to ArrayIndexOutOfBoundsException",
    "systemSpecification": true,
    "version": "1.5R5"
}